Workbook
Name Slicer_Discount_category: #N/A
Name Slicer_Price_category: #N/A
Name Slicer_Rating_category: #N/A

Sheet Raw data
A1: Product | B1: Current price | C1: old price | D1: Discount | E1: Review | F1: Ratingd
A2: 115 Piece Set Of Multifunctional Precision Screwdrivers | B2: KSh 950 | C2: KSh 1,525 | D2: 0.38 | E2: -2 | F2: 4.5 out of 5
A3: Metal Decorative Hooks Key Hangers Entryway Wall Hooks Towel Hooks - Home | B3: KSh 527 | C3: KSh 999 | D3: 0.47 | E3: -14 | F3: 4.1 out of 5
A4: Portable Mini Cordless Car Vacuum Cleaner - Blue | B4: KSh 2,199 | C4: KSh 2,923 | D4: 0.25 | E4: -24 | F4: 4.6 out of 5
A5: Weighing Scale Digital Bathroom Body Fat Scale USB-Black | B5: KSh 1,580 | C5: KSh 2,499 | D5: 0.37 | E5: -7 | F5: 4.7 out of 5
A6: Portable Home Small Air Humidifier 3-Speed Fan - Green | B6: KSh 1,740 | C6: KSh 2,356 | D6: 0.26 | E6: -5 | F6: 4.8 out of 5
A7: 220V 60W Electric Soldering Iron Kits With Tools, Tips, And Multimeter | B7: KSh 2,999 | C7: KSh 3,290 | D7: 0.09 | E7: -15 | F7: 4 out of 5
A8: 137 Pieces Cake Decorating Tool Set Baking Supplies | B8: KSh 2,319 | C8: KSh 3,032 | D8: 0.24 | E8: -55 | F8: 4.6 out of 5
A9: Desk Foldable Fan Adjustable Fan Strong Wind 3 Gear Usb | B9: KSh 988 | C9: KSh 1,580 | D9: 0.37 | E9: -2 | F9: 4 out of 5
A10: LASA FOLDING TABLE SERVING STAND | B10: KSh 1,274 | C10: KSh 2,800 | D10: 0.55 | E10: -5 | F10: 4.8 out of 5
A11: 13 In 1 Home Repair Tools Box Kit Set | B11: KSh 1,600 | C11: KSh 2,929 | D11: 0.45 | E11: -5 | F11: 3.8 out of 5
A12: Genebre 115 In 1 Screwdriver Repairing Tool Set For IPhone Cellphone Hand Tool | B12: KSh 799 | C12: KSh 999 | D12: 0.2 | E12: -12 | F12: 4.1 out of 5
A13: 100 Pcs Crochet Hook Tool Set Knitting Hook Set With Box | B13: KSh 990 | C13: KSh 1,500 | D13: 0.34 | E13: -39 | F13: 4.7 out of 5
... A22: 3PCS Single Head Knitting Crochet Sweater Needle Set | B22: KSh 38 | C22: KSh 80 | D22: 0.53 | E22: -13 | F22: 3.3 out of 5
A23: 4pcs Bathroom/Kitchen Towel Rack,Roll Paper Holder,Towel Bars,Hook | B23: KSh 1,860 | C23: KSh 3,220 | D23: 0.42
A24: LED Romantic Spaceship Starry Sky Projector,Children's Bedroom Night Light-Blue | B24: KSh 880 | C24: KSh 1,350 | D24: 0.35 | E24: -6 | F24: 4 out of 5
A25: Foldable Overbed Table/Desk | B25: KSh 1,650 | C25: KSh 2,150 | D25: 0.23 | E25: -14 | F25: 4.4 out of 5
A26: LASA 3 Tier Bamboo Shoe Bench Storage Shelf | B26: KSh 2,048 | C26: KSh 4,500 | D26: 0.54 | E26: -7 | F26: 4.3 out of 5
A27: Electronic Digital Display Vernier Caliper | B27: KSh 420 | C27: KSh 647 | D27: 0.35 | E27: -49 | F27: 4.6 out of 5
A28: Portable Wardrobe Nonwoven With 3 Hanging Rods And 6 Storage Shelves | B28: KSh 2,880 | C28: KSh 3,520 | D28: 0.18 | E28: -12 | F28: 3.8 out of 5
A29: 12 Litre Black Insulated Lunch Box | B29: KSh 1,350 | C29: KSh 1,990 | D29: 0.32 | E29: -13 | F29: 3.8 out of 5
A30: 52 Pieces Cake Decorating Tool Set Gift Kit Baking Supplies | B30: KSh 1,758 | C30: KSh 2,499 | D30: 0.3 | E30: -20 | F30: 4.1 out of 5
A31: MultiFunctional Storage Rack Multi-layer Bookshelf | B31: KSh 2,200 | C31: KSh 4,080 | D31: 0.46
A32: Exfoliate And Exfoliate Face Towel - Black | B32: KSh 185 | C32: KSh 382 | D32: 0.52 | E32: -9 | F32: 4.3 out of 5
A33: 12 Litre Insulated Lunch Box Grey | B33: KSh 980 | C33: KSh 1,490 | D33: 0.34 | E33: -12 | F33: 4.7 out of 5
A34: LED Eye Protection Desk Lamp , Study, Reading, USB Fan - Double Pen Holder | B34: KSh 1,820 | C34: KSh 3,490 | D34: 0.48 | E34: -9 | F34: 4.3 out of 5
A35: 53Pcs/Set Yarn Knitting Crochet Hooks With Bag - Fortune Cat | B35: KSh 1,940 | C35: KSh 2,650 | D35: 0.27 | E35: -20 | F35: 4.7 out of 5
A36: 53 Pieces/Set Yarn Knitting Crochet Hooks With Bag - Pansies | B36: KSh 1,980 | C36: KSh 2,699 | D36: 0.27 | E36: -32 | F36: 4.5 out of 5
A37: DIY File Folder, Office Drawer File Holder, Pen Holder, Desktop Storage Rack | B37: KSh 1,620 | C37: KSh 2,690 | D37: 0.4 | E37: -1 | F37: 5 out of 5
A38: Classic Black Cat Cotton Hemp Pillow Case For Home Car | B38: KSh 171 | C38: KSh 360 | D38: 0.53 | E38: -2 | F38: 5 out of 5
A39: Punch-free Great Load Bearing Bathroom Storage Rack Wall Shelf-White | B39: KSh 389 | C39: KSh 656 | D39: 0.41 | E39: -36 | F39: 4.3 out of 5
A40: 1/2/3 Seater Elastic Sofa Cover,Living Room/Home Decor Chair Cover-Grey | B40: KSh 1,620 - KSh 1,980 | C40: KSh 2,200 - KSh 3,200 | D40: 0.38 | E40: -2 | F40: 4.5 out of 5
A41: LASA Stainless Steel Double Wall Mount Soap Dispenser - 500ml | B41: KSh 2,750 | C41: KSh 4,471 | D41: 0.38
A42: 4M Float Switch Water Level Controller -Water Tank | B42: KSh 475 | C42: KSh 931 | D42: 0.49
A43: Modern Sofa Throw Pillow Cover-45x45cm-Blue&Red | B43: KSh 238 | C43: KSh 476 | D43: 0.5
A44: Balloon Insert, Birthday Party Balloon Set, PU Leather | B44: KSh 610 | C44: KSh 1,060 | D44: 0.42
A45: Balloon Insert, Birthday Party Balloon Set, PU Leather | B45: KSh 610 | C45: KSh 1,060 | D45: 0.42
A46: Shower Cap Wide Elastic Band Cover Reusable Bashroom Cap | B46: KSh 2,132 | C46: KSh 2,169 | D46: 0.02
A47: Christmas Elk Fence Yard Lawn Decorations Cute For Holidays | B47: KSh 999 | C47: KSh 2,000 | D47: 0.5
A48: 60W Hot Melt Glue Sprayer - Efficient And Stable Glue Dispensing | B48: KSh 1,190 | C48: KSh 1,785 | D48: 0.33
...

Sheet Cleaned data
A1: Product | B1: Current price | C1: Old price | D1: Price category | E1: Absolute Discount | F1: Discount(%) | G1: Discount category | H1: Review | I1: Rating (out of 5) | J1: Rating category
A2: 1/2/3 Seater Elastic Sofa Cover,Living Room/Home Decor Chair Cover-Grey | B2: 1800 | C2: 2700 | D2: =IF(B2<1300,"Budget friendly",IF(B2>2500,"Premium","Value")) -> Value | E2: ='Cleaned data'!$C52-'Cleaned data'!$B52 -> 151 | F2: 0.38 | G2: =IF(F2<0.2,"Low discount",IF(F2>0.4,"High discount","Medium discount")) -> Medium discount | H2: 2 | I2: 4.5 | J2: =IF(ISBLANK(I2),"Not provided",IF(I2<3,"Poor",IF(I2>4.5,"Excellent","Average"))) -> Average
A3: 100 Pcs Crochet Hook Tool Set Knitting Hook Set With Box | B3: 990 | C3: 1500 | D3: =IF(B3<1300,"Budget friendly",IF(B3>2500,"Premium","Value")) -> Budget friendly | E3: ='Cleaned data'!$C6-'Cleaned data'!$B6 -> 510 | F3: 0.34 | G3: =IF(F3<0.2,"Low discount",IF(F3>0.4,"High discount","Medium discount")) -> Medium discount | H3: 39 | I3: 4.7 | J3: =IF(ISBLANK(I3),"Not provided",IF(I3<3,"Poor",IF(I3>4.5,"Excellent","Average"))) -> Excellent
A4: 115 Piece Set Of Multifunctional Precision Screwdrivers | B4: 950 | C4: 1525 | D4: =IF(B4<1300,"Budget friendly",IF(B4>2500,"Premium","Value")) -> Budget friendly | E4: ='Cleaned data'!$C47-'Cleaned data'!$B47 -> -1984.9024 | F4: 0.38 | G4: =IF(F4<0.2,"Low discount",IF(F4>0.4,"High discount","Medium discount")) -> Medium discount | H4: 2 | I4: 4.5 | J4: =IF(ISBLANK(I4),"Not provided",IF(I4<3,"Poor",IF(I4>4.5,"Excellent","Average"))) -> Average
A5: 12 Litre Black Insulated Lunch Box | B5: 1350 | C5: 1990 | D5: =IF(B5<1300,"Budget friendly",IF(B5>2500,"Premium","Value")) -> Value | E5: ='Cleaned data'!$C19-'Cleaned data'!$B19 -> 1000 | F5: 0.32 | G5: =IF(F5<0.2,"Low discount",IF(F5>0.4,"High discount","Medium discount")) -> Medium discount | H5: 13 | I5: 3.8 | J5: =IF(ISBLANK(I5),"Not provided",IF(I5<3,"Poor",IF(I5>4.5,"Excellent","Average"))) -> Average
A6: 12 Litre Insulated Lunch Box Grey | B6: 980 | C6: 1490 | D6: =IF(B6<1300,"Budget friendly",IF(B6>2500,"Premium","Value")) -> Budget friendly | E6: ='Cleaned data'!$C24-'Cleaned data'!$B24 -> 483 | F6: 0.34 | G6: =IF(F6<0.2,"Low discount",IF(F6>0.4,"High discount","Medium discount")) -> Medium discount | H6: 12 | I6: 4.7 | J6: =IF(ISBLANK(I6),"Not provided",IF(I6<3,"Poor",IF(I6>4.5,"Excellent","Average"))) -> Excellent
A7: 120W Cordless Vacuum Cleaners Handheld Electric Vacuum Cleaner | B7: 445 | C7: 873 | D7: =IF(B7<1300,"Budget friendly",IF(B7>2500,"Premium","Value")) -> Budget friendly | E7: ='Cleaned data'!$C2-'Cleaned data'!$B2 -> 900 | F7: 0.49 | G7: =IF(F7<0.2,"Low discount",IF(F7>0.4,"High discount","Medium discount")) -> High discount | H7: 69 | I7: 2.8 | J7: =IF(ISBLANK(I7),"Not provided",IF(I7<3,"Poor",IF(I7>4.5,"Excellent","Average"))) -> Poor
A8: 12V 19500rpm Handheld Electric Angle Grinder Tool - UK - Yellow/Black | B8: 2799 | C8: 3810 | D8: =IF(B8<1300,"Budget friendly",IF(B8>2500,"Premium","Value")) -> Premium | E8: ='Cleaned data'!$C79-'Cleaned data'!$B79 -> 1721 | F8: 0.27 | G8: =IF(F8<0.2,"Low discount",IF(F8>0.4,"High discount","Medium discount")) -> Medium discount | J8: =IF(ISBLANK(I8),"Not provided",IF(I8<3,"Poor",IF(I8>4.5,"Excellent","Average"))) -> Not provided
A9: 13 In 1 Home Repair Tools Box Kit Set | B9: 1600 | C9: 2929 | D9: =IF(B9<1300,"Budget friendly",IF(B9>2500,"Premium","Value")) -> Value | E9: ='Cleaned data'!$C41-'Cleaned data'!$B41 -> 768 | F9: 0.45 | G9: =IF(F9<0.2,"Low discount",IF(F9>0.4,"High discount","Medium discount")) -> High discount | H9: 5 | I9: 3.8 | J9: =IF(ISBLANK(I9),"Not provided",IF(I9<3,"Poor",IF(I9>4.5,"Excellent","Average"))) -> Average
A10: 137 Pieces Cake Decorating Tool Set Baking Supplies | B10: 2319 | C10: 3032 | D10: =IF(B10<1300,"Budget friendly",IF(B10>2500,"Premium","Value")) -> Value | E10: ='Cleaned data'!$C3-'Cleaned data'!$B3 -> 510 | F10: 0.24 | G10: =IF(F10<0.2,"Low discount",IF(F10>0.4,"High discount","Medium discount")) -> Medium discount | H10: 55 | I10: 4.6 | J10: =IF(ISBLANK(I10),"Not provided",IF(I10<3,"Poor",IF(I10>4.5,"Excellent","Average"))) -> Excellent
A11: 1PC Refrigerator Food Seal Pocket Fridge Bags | B11: 198 | C11: 260 | D11: =IF(B11<1300,"Budget friendly",IF(B11>2500,"Premium","Value")) -> Budget friendly | E11: ='Cleaned data'!$C107-'Cleaned data'!$B107 -> 37 | F11: 0.24 | G11: =IF(F11<0.2,"Low discount",IF(F11>0.4,"High discount","Medium discount")) -> Medium discount | J11: =IF(ISBLANK(I11),"Not provided",IF(I11<3,"Poor",IF(I11>4.5,"Excellent","Average"))) -> Not provided
A12: 2 Pairs Cowhide Split Leather Work Gloves.32â„‰ Or Above Welding Gloves | B12: 1666 | C12: 1699 | D12: =IF(B12<1300,"Budget friendly",IF(B12>2500,"Premium","Value")) -> Value | E12: ='Cleaned data'!$C86-'Cleaned data'!$B86 -> 472 | F12: 0.02 | G12: =IF(F12<0.2,"Low discount",IF(F12>0.4,"High discount","Medium discount")) -> Low discount | J12: =IF(ISBLANK(I12),"Not provided",IF(I12<3,"Poor",IF(I12>4.5,"Excellent","Average"))) -> Not provided
A13: 220V 60W Electric Soldering Iron Kits With Tools, Tips, And Multimeter | B13: 2999 | C13: 3290 | D13: =IF(B13<1300,"Budget friendly",IF(B13>2500,"Premium","Value")) -> Premium | E13: ='Cleaned data'!$C14-'Cleaned data'!$B14 -> 24 | F13: 0.09 | G13: =IF(F13<0.2,"Low discount",IF(F13>0.4,"High discount","Medium discount")) -> Low discount | H13: 15 | I13: 4 | J13: =IF(ISBLANK(I13),"Not provided",IF(I13<3,"Poor",IF(I13>4.5,"Excellent","Average"))) -> Average
A14: 24 Grid Wall-mounted Sundries Organiser Fabric Closet Bag Storage Rack | B14: 1875 | C14: 1899 | D14: =IF(B14<1300,"Budget friendly",IF(B14>2500,"Premium","Value")) -> Value | E14: ='Cleaned data'!$C106-'Cleaned data'!$B106 -> 95 | F14: 0.01 | G14: =IF(F14<0.2,"Low discount",IF(F14>0.4,"High discount","Medium discount")) -> Low discount | J14: =IF(ISBLANK(I14),"Not provided",IF(I14<3,"Poor",IF(I14>4.5,"Excellent","Average"))) -> Not provided
A15: 2PCS Ice Silk Square Cushion Cover Pillowcases - 65x65cm | B15: 1200 | C15: 2400 | D15: =IF(B15<1300,"Budget friendly",IF(B15>2500,"Premium","Value")) -> Budget friendly | E15: ='Cleaned data'!$C98-'Cleaned data'!$B98 -> 39 | F15: 0.5 | G15: =IF(F15<0.2,"Low discount",IF(F15>0.4,"High discount","Medium discount")) -> High discount | J15: =IF(ISBLANK(I15),"Not provided",IF(I15<3,"Poor",IF(I15>4.5,"Excellent","Average"))) -> Not provided
A16: 2pcs Solar Street Light Flood Light Outdoor | B16: 1200 | C16: 1950 | D16: =IF(B16<1300,"Budget friendly",IF(B16>2500,"Premium","Value")) -> Budget friendly | E16: ='Cleaned data'!$C69-'Cleaned data'!$B69 -> 500 | F16: 0.38 | G16: =IF(F16<0.2,"Low discount",IF(F16>0.4,"High discount","Medium discount")) -> Medium discount | J16: =IF(ISBLANK(I16),"Not provided",IF(I16<3,"Poor",IF(I16>4.5,"Excellent","Average"))) -> Not provided
A17: 2PCS/LOT Solar LED Outdoor Intelligent Light Controlled Wall Lamp | B17: 790 | C17: 1485 | D17: =IF(B17<1300,"Budget friendly",IF(B17>2500,"Premium","Value")) -> Budget friendly | E17: ='Cleaned data'!$C81-'Cleaned data'!$B81 -> 1670 | F17: 0.47 | G17: =IF(F17<0.2,"Low discount",IF(F17>0.4,"High discount","Medium discount")) -> High discount | J17: =IF(ISBLANK(I17),"Not provided",IF(I17<3,"Poor",IF(I17>4.5,"Excellent","Average"))) -> Not provided
A18: 32PCS Portable Cordless Drill Set With Cyclic Battery Drive -26 Variable Speed | B18: 3750 | C18: 6143 | D18: =IF(B18<1300,"Budget friendly",IF(B18>2500,"Premium","Value")) -> Premium | E18: ='Cleaned data'!$C43-'Cleaned data'!$B43 -> 352 | F18: 0.39 | G18: =IF(F18<0.2,"Low discount",IF(F18>0.4,"High discount","Medium discount")) -> Medium discount | H18: 5 | I18: 3 | J18: =IF(ISBLANK(I18),"Not provided",IF(I18<3,"Poor",IF(I18>4.5,"Excellent","Average"))) -> Average
A19: 380ML USB Rechargeable Portable Small Blenders And Juicers | B19: 1000 | C19: 2000 | D19: =IF(B19<1300,"Budget friendly",IF(B19>2500,"Premium","Value")) -> Budget friendly | E19: ='Cleaned data'!$C31-'Cleaned data'!$B31 -> 830 | F19: 0.5 | G19: =IF(F19<0.2,"Low discount",IF(F19>0.4,"High discount","Medium discount")) -> High discount | H19: 7 | I19: 2.3 | J19: =IF(ISBLANK(I19),"Not provided",IF(I19<3,"Poor",IF(I19>4.5,"Excellent","Average"))) -> Poor
A20: 3D Waterproof EVA Plastic Shower Curtain 1.8*2Mtrs | B20: 998 | C20: 1966 | D20: =IF(B20<1300,"Budget friendly",IF(B20>2500,"Premium","Value")) -> Budget friendly | E20: ='Cleaned data'!$C5-'Cleaned data'!$B5 -> 640 | F20: 0.49 | G20: =IF(F20<0.2,"Low discount",IF(F20>0.4,"High discount","Medium discount")) -> High discount | H20: 44 | I20: 4.6 | J20: =IF(ISBLANK(I20),"Not provided",IF(I20<3,"Poor",IF(I20>4.5,"Excellent","Average"))) -> Excellent
A21: 3PCS Rotary Scraper Thermomix For Kitchen | B21: 690 | C21: 1200 | D21: =IF(B21<1300,"Budget friendly",IF(B21>2500,"Premium","Value")) -> Budget friendly | E21: ='Cleaned data'!$C82-'Cleaned data'!$B82 -> 470 | F21: 0.43 | G21: =IF(F21<0.2,"Low discount",IF(F21>0.4,"High discount","Medium discount")) -> High discount | J21: =IF(ISBLANK(I21),"Not provided",IF(I21<3,"Poor",IF(I21>4.5,"Excellent","Average"))) -> Not provided
A22: 3PCS Single Head Knitting Crochet Sweater Needle Set | B22: 38 | C22: 80 | D22: =IF(B22<1300,"Budget friendly",IF(B22>2500,"Premium","Value")) -> Budget friendly | E22: ='Cleaned data'!$C18-'Cleaned data'!$B18 -> 2393 | F22: 0.53 | G22: =IF(F22<0.2,"Low discount",IF(F22>0.4,"High discount","Medium discount")) -> High discount | H22: 13 | I22: 3.3 | J22: =IF(ISBLANK(I22),"Not provided",IF(I22<3,"Poor",IF(I22>4.5,"Excellent","Average"))) -> Average
A23: 4 Piece Coloured Stainless Steel Kitchenware Set | B23: 248 | C23: 486 | D23: =IF(B23<1300,"Budget friendly",IF(B23>2500,"Premium","Value")) -> Budget friendly | E23: ='Cleaned data'!$C101-'Cleaned data'!$B101 -> 724 | F23: 0.49 | G23: =IF(F23<0.2,"Low discount",IF(F23>0.4,"High discount","Medium discount")) -> High discount | J23: =IF(ISBLANK(I23),"Not provided",IF(I23<3,"Poor",IF(I23>4.5,"Excellent","Average"))) -> Not provided
A24: 40cm Gold DIY Acrylic Wall Sticker Clock | B24: 552 | C24: 1035 | D24: =IF(B24<1300,"Budget friendly",IF(B24>2500,"Premium","Value")) -> Budget friendly | E24: ='Cleaned data'!$C22-'Cleaned data'!$B22 -> 42 | F24: 0.47 | G24: =IF(F24<0.2,"Low discount",IF(F24>0.4,"High discount","Medium discount")) -> High discount | H24: 12 | I24: 4.8 | J24: =IF(ISBLANK(I24),"Not provided",IF(I24<3,"Poor",IF(I24>4.5,"Excellent","Average"))) -> Excellent
A25: 4M Float Switch Water Level Controller -Water Tank | B25: 475 | C25: 931 | D25: =IF(B25<1300,"Budget friendly",IF(B25>2500,"Premium","Value")) -> Budget friendly | E25: ='Cleaned data'!$C62-'Cleaned data'!$B62 -> 67 | F25: 0.49 | G25: =IF(F25<0.2,"Low discount",IF(F25>0.4,"High discount","Medium discount")) -> High discount | J25: =IF(ISBLANK(I25),"Not provided",IF(I25<3,"Poor",IF(I25>4.5,"Excellent","Average"))) -> Not provided
A26: 4pcs Bathroom/Kitchen Towel Rack,Roll Paper Holder,Towel Bars,Hook | B26: 1860 | C26: 3220 | D26: =IF(B26<1300,"Budget friendly",IF(B26>2500,"Premium","Value")) -> Value | E26: ='Cleaned data'!$C59-'Cleaned data'!$B59 -> 189 | F26: 0.42 | G26: =IF(F26<0.2,"Low discount",IF(F26>0.4,"High discount","Medium discount")) -> High discount | J26: =IF(ISBLANK(I26),"Not provided",IF(I26<3,"Poor",IF(I26>4.5,"Excellent","Average"))) -> Not provided
A27: 5 Pieces/set Of Stainless Steel Induction Cooker Pots | B27: 2170 | C27: 2500 | D27: =IF(B27<1300,"Budget friendly",IF(B27>2500,"Premium","Value")) -> Value | E27: ='Cleaned data'!$C35-'Cleaned data'!$B35 -> 595 | F27: 0.13 | G27: =IF(F27<0.2,"Low discount",IF(F27>0.4,"High discount","Medium discount")) -> Low discount | H27: 6 | I27: 2.5 | J27: =IF(ISBLANK(I27),"Not provided",IF(I27<3,"Poor",IF(I27>4.5,"Excellent","Average"))) -> Poor
A28: 52 Pieces Cake Decorating Tool Set Gift Kit Baking Supplies | B28: 1758 | C28: 2499 | D28: =IF(B28<1300,"Budget friendly",IF(B28>2500,"Premium","Value")) -> Value | E28: ='Cleaned data'!$C10-'Cleaned data'!$B10 -> 713 | F28: 0.3 | G28: =IF(F28<0.2,"Low discount",IF(F28>0.4,"High discount","Medium discount")) -> Medium discount | H28: 20 | I28: 4.1 | J28: =IF(ISBLANK(I28),"Not provided",IF(I28<3,"Poor",IF(I28>4.5,"Excellent","Average"))) -> Average
A29: 53 Pieces/Set Yarn Knitting Crochet Hooks With Bag - Pansies | B29: 1980 | C29: 2699 | D29: =IF(B29<1300,"Budget friendly",IF(B29>2500,"Premium","Value")) -> Value | E29: ='Cleaned data'!$C8-'Cleaned data'!$B8 -> 1011 | F29: 0.27 | G29: =IF(F29<0.2,"Low discount",IF(F29>0.4,"High discount","Medium discount")) -> Medium discount | H29: 32 | I29: 4.5 | J29: =IF(ISBLANK(I29),"Not provided",IF(I29<3,"Poor",IF(I29>4.5,"Excellent","Average"))) -> Average
A30: 53Pcs/Set Yarn Knitting Crochet Hooks With Bag - Fortune Cat | B30: 1940 | C30: 2650 | D30: =IF(B30<1300,"Budget friendly",IF(B30>2500,"Premium","Value")) -> Value | E30: ='Cleaned data'!$C11-'Cleaned data'!$B11 -> 62 | F30: 0.27 | G30: =IF(F30<0.2,"Low discount",IF(F30>0.4,"High discount","Medium discount")) -> Medium discount | H30: 20 | I30: 4.7 | J30: =IF(ISBLANK(I30),"Not provided",IF(I30<3,"Poor",IF(I30>4.5,"Excellent","Average"))) -> Excellent
A31: 5m Waterproof Spherical LED String Lights Outdoor Ball Chain Lights Party Lighting Decoration Adjustable | B31: 1460 | C31: 2290 | D31: =IF(B31<1300,"Budget friendly",IF(B31>2500,"Premium","Value")) -> Value | E31: ='Cleaned data'!$C85-'Cleaned data'!$B85 -> 1010 | F31: 0.36 | G31: =IF(F31<0.2,"Low discount",IF(F31>0.4,"High discount","Medium discount")) -> Medium discount | J31: =IF(ISBLANK(I31),"Not provided",IF(I31<3,"Poor",IF(I31>4.5,"Excellent","Average"))) -> Not provided
A32: 5-PCS Stainless Steel Cooking Pot Set With Steamed Slices | B32: 2115 | C32: 4700 | D32: =IF(B32<1300,"Budget friendly",IF(B32>2500,"Premium","Value")) -> Value | E32: ='Cleaned data'!$C20-'Cleaned data'!$B20 -> 968 | F32: 0.55 | G32: =IF(F32<0.2,"Low discount",IF(F32>0.4,"High discount","Medium discount")) -> High discount | H32: 13 | I32: 2.1 | J32: =IF(ISBLANK(I32),"Not provided",IF(I32<3,"Poor",IF(I32>4.5,"Excellent","Average"))) -> Poor
A33: 6 In 1 Bottle Can Opener Multifunctional Easy Opener | B33: 199 | C33: 553 | D33: =IF(B33<1300,"Budget friendly",IF(B33>2500,"Premium","Value")) -> Budget friendly | E33: ='Cleaned data'!$C112-'Cleaned data'!$B112 -> 31 | F33: 0.64 | G33: =IF(F33<0.2,"Low discount",IF(F33>0.4,"High discount","Medium discount")) -> High discount | J33: =IF(ISBLANK(I33),"Not provided",IF(I33<3,"Poor",IF(I33>4.5,"Excellent","Average"))) -> Not provided
A34: 6 Layers Steel Pipe Assembling Dustproof Storage Shoe Cabinet | B34: 899 | C34: 1699 | D34: =IF(B34<1300,"Budget friendly",IF(B34>2500,"Premium","Value")) -> Budget friendly | E34: ='Cleaned data'!$C97-'Cleaned data'!$B97 -> 165 | F34: 0.47 | G34: =IF(F34<0.2,"Low discount",IF(F34>0.4,"High discount","Medium discount")) -> High discount | J34: =IF(ISBLANK(I34),"Not provided",IF(I34<3,"Poor",IF(I34>4.5,"Excellent","Average"))) -> Not provided
A35: 60W Hot Melt Glue Sprayer - Efficient And Stable Glue Dispensing | B35: 1190 | C35: 1785 | D35: =IF(B35<1300,"Budget friendly",IF(B35>2500,"Premium","Value")) -> Budget friendly | E35: ='Cleaned data'!$C67-'Cleaned data'!$B67 -> 227 | F35: 0.33 | G35: =IF(F35<0.2,"Low discount",IF(F35>0.4,"High discount","Medium discount")) -> Medium discount | J35: =IF(ISBLANK(I35),"Not provided",IF(I35<3,"Poor",IF(I35>4.5,"Excellent","Average"))) -> Not provided
A36: 7PCS Silicone Thumb Knife Finger Protector Vegetable Harvesting Knife | B36: 230 | C36: 450 | D36: =IF(B36<1300,"Budget friendly",IF(B36>2500,"Premium","Value")) -> Budget friendly | E36: ='Cleaned data'!$C84-'Cleaned data'!$B84 -> 700 | F36: 0.49 | G36: =IF(F36<0.2,"Low discount",IF(F36>0.4,"High discount","Medium discount")) -> High discount | J36: =IF(ISBLANK(I36),"Not provided",IF(I36<3,"Poor",IF(I36>4.5,"Excellent","Average"))) -> Not provided
A37: 7-piece Set Of Storage Bags, Travel Storage Bags, Shoe Bags | B37: 968 | C37: 1814 | D37: =IF(B37<1300,"Budget friendly",IF(B37>2500,"Premium","Value")) -> Budget friendly | E37: ='Cleaned data'!$C38-'Cleaned data'!$B38 -> 794 | F37: 0.47 | G37: =IF(F37<0.2,"Low discount",IF(F37>0.4,"High discount","Medium discount")) -> High discount | H37: 6 | I37: 2.2 | J37: =IF(ISBLANK(I37),"Not provided",IF(I37<3,"Poor",IF(I37>4.5,"Excellent","Average"))) -> Poor
A38: 8in1 Screwdriver With LED Light | B38: 1080 | C38: 1874 | D38: =IF(B38<1300,"Budget friendly",IF(B38>2500,"Premium","Value")) -> Budget friendly | E38: ='Cleaned data'!$C104-'Cleaned data'!$B104 -> 1200 | F38: 0.42 | G38: =IF(F38<0.2,"Low discount",IF(F38>0.4,"High discount","Medium discount")) -> High discount | J38: =IF(ISBLANK(I38),"Not provided",IF(I38<3,"Poor",IF(I38>4.5,"Excellent","Average"))) -> Not provided
A39: 9pcs Gas Mask, For Painting, Dust, Formaldehyde Grinding, Polishing | B39: 1420 | C39: 2420 | D39: =IF(B39<1300,"Budget friendly",IF(B39>2500,"Premium","Value")) -> Value | E39: ='Cleaned data'!$C105-'Cleaned data'!$B105 -> 267 | F39: 0.41 | G39: =IF(F39<0.2,"Low discount",IF(F39>0.4,"High discount","Medium discount")) -> High discount | J39: =IF(ISBLANK(I39),"Not provided",IF(I39<3,"Poor",IF(I39>4.5,"Excellent","Average"))) -> Not provided
A40: Agapeon Toothbrush Holder And Toothpaste Dispenser | B40: 382 | C40: 700 | D40: =IF(B40<1300,"Budget friendly",IF(B40>2500,"Premium","Value")) -> Budget friendly | E40: ='Cleaned data'!$C12-'Cleaned data'!$B12 -> 33 | F40: 0.45 | G40: =IF(F40<0.2,"Low discount",IF(F40>0.4,"High discount","Medium discount")) -> High discount | H40: 17 | I40: 2.6 | J40: =IF(ISBLANK(I40),"Not provided",IF(I40<3,"Poor",IF(I40>4.5,"Excellent","Average"))) -> Poor
...

Sheet Dashboard
W9: TOP 10 HIGHEST RATED PRODUCTS | X9: Average of Rating (out of 5)
W10: 40cm Gold DIY Acrylic Wall Sticker Clock | X10: 4.8
W11: Anti-Skid Absorbent Insulation Coaster For Home Office | X11: 5
W12: Bedroom Simple Floor Hanging Clothes Rack Single Pole Hat Rack - White | X12: 5
W13: Classic Black Cat Cotton Hemp Pillow Case For Home Car | X13: 5
W14: DIY File Folder, Office Drawer File Holder, Pen Holder, Desktop Storage Rack | X14: 5
W15: Konka Healty Electric Kettle, 24-hour Heat Preservation,1.5L,800W, White | X15: 5
W16: LASA Aluminum Folding Truck Hand Cart - 68kg Max | X16: 5
W17: LASA FOLDING TABLE SERVING STAND | X17: 4.8
W18: Peacock Throw Pillow Cushion Case For Home Car | X18: 5
W19: Portable Home Small Air Humidifier 3-Speed Fan - Green | X19: 4.8
W20: Grand Total | X20: 4.94
W22: TOP 10 PRODUCTS BY REVIEWS COUNT | X22: REVIEW COUNT
W23: 100 Pcs Crochet Hook Tool Set Knitting Hook Set With Box | X23: 39
W24: 120W Cordless Vacuum Cleaners Handheld Electric Vacuum Cleaner | X24: 69
W25: 137 Pieces Cake Decorating Tool Set Baking Supplies | X25: 55
W26: 3D Waterproof EVA Plastic Shower Curtain 1.8*2Mtrs | X26: 44
W27: 52 Pieces Cake Decorating Tool Set Gift Kit Baking Supplies | X27: 20
W28: 53 Pieces/Set Yarn Knitting Crochet Hooks With Bag - Pansies | X28: 32
W29: 53Pcs/Set Yarn Knitting Crochet Hooks With Bag - Fortune Cat | X29: 20
W30: Electronic Digital Display Vernier Caliper | X30: 49
W31: Portable Mini Cordless Car Vacuum Cleaner - Blue | X31: 24
W32: Punch-free Great Load Bearing Bathroom Storage Rack Wall Shelf-White | X32: 36
W33: TOTAL | X33: 388
W35: TOP 10 DISCOUNTED PRODUCTS | X35: DISCOUNT PERCENTAGE
W36: 3PCS Single Head Knitting Crochet Sweater Needle Set | X36: 0.53
W37: 5-PCS Stainless Steel Cooking Pot Set With Steamed Slices | X37: 0.55
W38: 6 In 1 Bottle Can Opener Multifunctional Easy Opener | X38: 0.64
W39: Classic Black Cat Cotton Hemp Pillow Case For Home Car | X39: 0.53
W40: Creative Owl Shape Keychain Black | X40: 0.55
W41: Exfoliate And Exfoliate Face Towel - Black | X41: 0.52
W42: Intelligent LED Body Sensor Wireless Lighting Night Light USB | X42: 0.52
S43: W | W43: LASA 3 Tier Bamboo Shoe Bench Storage Shelf | X43: 0.54
W44: LASA FOLDING TABLE SERVING STAND | X44: 0.55
W45: Mythco 120COB Solar Wall Ligt With Motion Sensor And Remote Control 3 Modes | X45: 0.54

Sheet Discount vs Reviews
A3: Row Labels | B3: Count of Review
A4: High discount | B4: 30
A5: Low discount | B5: 4
A6: Medium discount | B6: 23
A7: (blank)
A8: Grand Total | B8: 57

Sheet Rating vs Reviews
A3: Row Labels | B3: Count of Review
A4: Average | B4: 26
A5: Excellent | B5: 19
A6: Poor | B6: 12
A7: Grand Total | B7: 57

Sheet Price vs Rating
A3: Row Labels | B3: Average of Rating (out of 5)
A4: Budget friendly | B4: 3.759375
A5: Premium | B5: 4.08
A6: Value | B6: 4.05
A7: (blank)
A8: Grand Total | B8: 3.8894737

Sheet Top 10 reviews, discounts 
A1: PRODUCTS WITH THE HIGHEST CUSTOMER REVIEWS
A3: Row Labels | B3: Sum of Review
A4: 100 Pcs Crochet Hook Tool Set Knitting Hook Set With Box | B4: 39
A5: 120W Cordless Vacuum Cleaners Handheld Electric Vacuum Cleaner | B5: 69
A6: 137 Pieces Cake Decorating Tool Set Baking Supplies | B6: 55
A7: 3D Waterproof EVA Plastic Shower Curtain 1.8*2Mtrs | B7: 44
A8: 52 Pieces Cake Decorating Tool Set Gift Kit Baking Supplies | B8: 20
A9: 53 Pieces/Set Yarn Knitting Crochet Hooks With Bag - Pansies | B9: 32
A10: 53Pcs/Set Yarn Knitting Crochet Hooks With Bag - Fortune Cat | B10: 20
A11: Electronic Digital Display Vernier Caliper | B11: 49
A12: Portable Mini Cordless Car Vacuum Cleaner - Blue | B12: 24
A13: Punch-free Great Load Bearing Bathroom Storage Rack Wall Shelf-White | B13: 36
A14: Grand Total | B14: 388
A17: PRODUCTS WUTH THE HIGHEST DISCOUNTS
A19: Row Labels | B19: Average of Discount(%)
A20: 3PCS Single Head Knitting Crochet Sweater Needle Set | B20: 0.53
A21: 5-PCS Stainless Steel Cooking Pot Set With Steamed Slices | B21: 0.55
A22: 6 In 1 Bottle Can Opener Multifunctional Easy Opener | B22: 0.64
A23: Classic Black Cat Cotton Hemp Pillow Case For Home Car | B23: 0.53
A24: Creative Owl Shape Keychain Black | B24: 0.55
A25: Exfoliate And Exfoliate Face Towel - Black | B25: 0.52
A26: Intelligent LED Body Sensor Wireless Lighting Night Light USB | B26: 0.52
A27: LASA 3 Tier Bamboo Shoe Bench Storage Shelf | B27: 0.54
A28: LASA FOLDING TABLE SERVING STAND | B28: 0.55
A29: Mythco 120COB Solar Wall Ligt With Motion Sensor And Remote Control 3 Modes | B29: 0.54
A30: Grand Total | B30: 0.54727273

Sheet Top,Bottom rated products
A1: TOP 10 RATED PRODUCTS
A3: Row Labels | B3: Average of Rating (out of 5)
A4: 40cm Gold DIY Acrylic Wall Sticker Clock | B4: 4.8
A5: Anti-Skid Absorbent Insulation Coaster For Home Office | B5: 5
A6: Bedroom Simple Floor Hanging Clothes Rack Single Pole Hat Rack - White | B6: 5
A7: Classic Black Cat Cotton Hemp Pillow Case For Home Car | B7: 5
A8: DIY File Folder, Office Drawer File Holder, Pen Holder, Desktop Storage Rack | B8: 5
A9: Konka Healty Electric Kettle, 24-hour Heat Preservation,1.5L,800W, White | B9: 5
A10: LASA Aluminum Folding Truck Hand Cart - 68kg Max | B10: 5
A11: LASA FOLDING TABLE SERVING STAND | B11: 4.8
A12: Peacock Throw Pillow Cushion Case For Home Car | B12: 5
A13: Portable Home Small Air Humidifier 3-Speed Fan - Green | B13: 4.8
A14: Grand Total | B14: 4.94
A16: BOTTOM 10 RATED PRODUCTS
A18: Rating (out of 5) | B18: (Multiple Items)
A20: Row Labels | B20: Average of Rating (out of 5)
A21: 380ML USB Rechargeable Portable Small Blenders And Juicers | B21: 2.3
A22: 5 Pieces/set Of Stainless Steel Induction Cooker Pots | B22: 2.5
A23: 5-PCS Stainless Steel Cooking Pot Set With Steamed Slices | B23: 2.1
A24: 7-piece Set Of Storage Bags, Travel Storage Bags, Shoe Bags | B24: 2.2
A25: Agapeon Toothbrush Holder And Toothpaste Dispenser | B25: 2.6
A26: Artificial Potted Flowers Room Decorative Flowers (2 Pieces) | B26: 2.2
A27: Electric LED UV Mosquito Killer Lamp, Outdoor/Indoor Fly Killer Trap Light -USB | B27: 2.1
A28: Intelligent LED Body Sensor Wireless Lighting Night Light USB | B28: 2.7
A29: Wall-mounted Sticker Punch-free Plug Fixer | B29: 2
A30: Watercolour Gold Foil Textured Print Pillow Cover | B30: 2.3
A31: Grand Total | B31: 2.3

Sheet Product Perfromance Analysis
A2: Product perfromance analysis
A3: In the columns E: Discount, F: Discount percentage, H: Review and I: Rating, conditional formatting was applied; cells highlighted in green show the top 10 values in the respective columns.
A6: Product | B6: Current price | C6: Old price | D6: Price category | E6: Discount KES | F6: Discount(%) | G6: Discount category | H6: Review | I6: Rating (out of 5) | J6: Rating category
A7: 115 Piece Set Of Multifunctional Precision Screwdrivers | B7: 950 | C7: 1525 | D7: =IF(B7<1300,"Budget friendly",IF(B7>2500,"Premium","Value")) -> Budget friendly | E7: =Table22[[#This Row],[Old price]]-Table22[[#This Row],[Current price]] -> 575 | F7: 0.38 | G7: =IF(F7<0.2,"Low discount",IF(F7>0.4,"High discount","Medium discount")) -> Medium discount | H7: 2 | I7: 4.5 | J7: =IF(ISBLANK(I7),"Not provided",IF(I7<3,"Poor",IF(I7>4.5,"Excellent","Average"))) -> Average
A8: Metal Decorative Hooks Key Hangers Entryway Wall Hooks Towel Hooks - Home | B8: 527 | C8: 999 | D8: =IF(B8<1300,"Budget friendly",IF(B8>2500,"Premium","Value")) -> Budget friendly | E8: =Table22[[#This Row],[Old price]]-Table22[[#This Row],[Current price]] -> 472 | F8: 0.47 | G8: =IF(F8<0.2,"Low discount",IF(F8>0.4,"High discount","Medium discount")) -> High discount | H8: 14 | I8: 4.1 | J8: =IF(ISBLANK(I8),"Not provided",IF(I8<3,"Poor",IF(I8>4.5,"Excellent","Average"))) -> Average
A9: Portable Mini Cordless Car Vacuum Cleaner - Blue | B9: 2199 | C9: 2923 | D9: =IF(B9<1300,"Budget friendly",IF(B9>2500,"Premium","Value")) -> Value | E9: =Table22[[#This Row],[Old price]]-Table22[[#This Row],[Current price]] -> 724 | F9: 0.25 | G9: =IF(F9<0.2,"Low discount",IF(F9>0.4,"High discount","Medium discount")) -> Medium discount | H9: 24 | I9: 4.6 | J9: =IF(ISBLANK(I9),"Not provided",IF(I9<3,"Poor",IF(I9>4.5,"Excellent","Average"))) -> Excellent
A10: Weighing Scale Digital Bathroom Body Fat Scale USB-Black | B10: 1580 | C10: 2499 | D10: =IF(B10<1300,"Budget friendly",IF(B10>2500,"Premium","Value")) -> Value | E10: =Table22[[#This Row],[Old price]]-Table22[[#This Row],[Current price]] -> 919 | F10: 0.37 | G10: =IF(F10<0.2,"Low discount",IF(F10>0.4,"High discount","Medium discount")) -> Medium discount | H10: 7 | I10: 4.7 | J10: =IF(ISBLANK(I10),"Not provided",IF(I10<3,"Poor",IF(I10>4.5,"Excellent","Average"))) -> Excellent
A11: Portable Home Small Air Humidifier 3-Speed Fan - Green | B11: 1740 | C11: 2356 | D11: =IF(B11<1300,"Budget friendly",IF(B11>2500,"Premium","Value")) -> Value | E11: =Table22[[#This Row],[Old price]]-Table22[[#This Row],[Current price]] -> 616 | F11: 0.26 | G11: =IF(F11<0.2,"Low discount",IF(F11>0.4,"High discount","Medium discount")) -> Medium discount | H11: 5 | I11: 4.8 | J11: =IF(ISBLANK(I11),"Not provided",IF(I11<3,"Poor",IF(I11>4.5,"Excellent","Average"))) -> Excellent
A12: 220V 60W Electric Soldering Iron Kits With Tools, Tips, And Multimeter | B12: 2999 | C12: 3290 | D12: =IF(B12<1300,"Budget friendly",IF(B12>2500,"Premium","Value")) -> Premium | E12: =Table22[[#This Row],[Old price]]-Table22[[#This Row],[Current price]] -> 291 | F12: 0.09 | G12: =IF(F12<0.2,"Low discount",IF(F12>0.4,"High discount","Medium discount")) -> Low discount | H12: 15 | I12: 4 | J12: =IF(ISBLANK(I12),"Not provided",IF(I12<3,"Poor",IF(I12>4.5,"Excellent","Average"))) -> Average
A13: 137 Pieces Cake Decorating Tool Set Baking Supplies | B13: 2319 | C13: 3032 | D13: =IF(B13<1300,"Budget friendly",IF(B13>2500,"Premium","Value")) -> Value | E13: =Table22[[#This Row],[Old price]]-Table22[[#This Row],[Current price]] -> 713 | F13: 0.24 | G13: =IF(F13<0.2,"Low discount",IF(F13>0.4,"High discount","Medium discount")) -> Medium discount | H13: 55 | I13: 4.6 | J13: =IF(ISBLANK(I13),"Not provided",IF(I13<3,"Poor",IF(I13>4.5,"Excellent","Average"))) -> Excellent
A14: Desk Foldable Fan Adjustable Fan Strong Wind 3 Gear Usb | B14: 988 | C14: 1580 | D14: =IF(B14<1300,"Budget friendly",IF(B14>2500,"Premium","Value")) -> Budget friendly | E14: =Table22[[#This Row],[Old price]]-Table22[[#This Row],[Current price]] -> 592 | F14: 0.37 | G14: =IF(F14<0.2,"Low discount",IF(F14>0.4,"High discount","Medium discount")) -> Medium discount | H14: 2 | I14: 4 | J14: =IF(ISBLANK(I14),"Not provided",IF(I14<3,"Poor",IF(I14>4.5,"Excellent","Average"))) -> Average
A15: LASA FOLDING TABLE SERVING STAND | B15: 1274 | C15: 2800 | D15: =IF(B15<1300,"Budget friendly",IF(B15>2500,"Premium","Value")) -> Budget friendly | E15: =Table22[[#This Row],[Old price]]-Table22[[#This Row],[Current price]] -> 1526 | F15: 0.55 | G15: =IF(F15<0.2,"Low discount",IF(F15>0.4,"High discount","Medium discount")) -> High discount | H15: 5 | I15: 4.8 | J15: =IF(ISBLANK(I15),"Not provided",IF(I15<3,"Poor",IF(I15>4.5,"Excellent","Average"))) -> Excellent
A16: 13 In 1 Home Repair Tools Box Kit Set | B16: 1600 | C16: 2929 | D16: =IF(B16<1300,"Budget friendly",IF(B16>2500,"Premium","Value")) -> Value | E16: =Table22[[#This Row],[Old price]]-Table22[[#This Row],[Current price]] -> 1329 | F16: 0.45 | G16: =IF(F16<0.2,"Low discount",IF(F16>0.4,"High discount","Medium discount")) -> High discount | H16: 5 | I16: 3.8 | J16: =IF(ISBLANK(I16),"Not provided",IF(I16<3,"Poor",IF(I16>4.5,"Excellent","Average"))) -> Average
A17: Genebre 115 In 1 Screwdriver Repairing Tool Set For IPhone Cellphone Hand Tool | B17: 799 | C17: 999 | D17: =IF(B17<1300,"Budget friendly",IF(B17>2500,"Premium","Value")) -> Budget friendly | E17: =Table22[[#This Row],[Old price]]-Table22[[#This Row],[Current price]] -> 200 | F17: 0.2 | G17: =IF(F17<0.2,"Low discount",IF(F17>0.4,"High discount","Medium discount")) -> Medium discount | H17: 12 | I17: 4.1 | J17: =IF(ISBLANK(I17),"Not provided",IF(I17<3,"Poor",IF(I17>4.5,"Excellent","Average"))) -> Average
A18: 100 Pcs Crochet Hook Tool Set Knitting Hook Set With Box | B18: 990 | C18: 1500 | D18: =IF(B18<1300,"Budget friendly",IF(B18>2500,"Premium","Value")) -> Budget friendly | E18: =Table22[[#This Row],[Old price]]-Table22[[#This Row],[Current price]] -> 510 | F18: 0.34 | G18: =IF(F18<0.2,"Low discount",IF(F18>0.4,"High discount","Medium discount")) -> Medium discount | H18: 39 | I18: 4.7 | J18: =IF(ISBLANK(I18),"Not provided",IF(I18<3,"Poor",IF(I18>4.5,"Excellent","Average"))) -> Excellent
... A27: 3PCS Single Head Knitting Crochet Sweater Needle Set | B27: 38 | C27: 80 | D27: =IF(B27<1300,"Budget friendly",IF(B27>2500,"Premium","Value")) -> Budget friendly | E27: =Table22[[#This Row],[Old price]]-Table22[[#This Row],[Current price]] -> 42 | F27: 0.53 | G27: =IF(F27<0.2,"Low discount",IF(F27>0.4,"High discount","Medium discount")) -> High discount | H27: 13 | I27: 3.3 | J27: =IF(ISBLANK(I27),"Not provided",IF(I27<3,"Poor",IF(I27>4.5,"Excellent","Average"))) -> Average
A28: 4pcs Bathroom/Kitchen Towel Rack,Roll Paper Holder,Towel Bars,Hook | B28: 1860 | C28: 3220 | D28: =IF(B28<1300,"Budget friendly",IF(B28>2500,"Premium","Value")) -> Value | E28: =Table22[[#This Row],[Old price]]-Table22[[#This Row],[Current price]] -> 1360 | F28: 0.42 | G28: =IF(F28<0.2,"Low discount",IF(F28>0.4,"High discount","Medium discount")) -> High discount | J28: =IF(ISBLANK(I28),"Not provided",IF(I28<3,"Poor",IF(I28>4.5,"Excellent","Average"))) -> Not provided
A29: LED Romantic Spaceship Starry Sky Projector,Children's Bedroom Night Light-Blue | B29: 880 | C29: 1350 | D29: =IF(B29<1300,"Budget friendly",IF(B29>2500,"Premium","Value")) -> Budget friendly | E29: =Table22[[#This Row],[Old price]]-Table22[[#This Row],[Current price]] -> 470 | F29: 0.35 | G29: =IF(F29<0.2,"Low discount",IF(F29>0.4,"High discount","Medium discount")) -> Medium discount | H29: 6 | I29: 4 | J29: =IF(ISBLANK(I29),"Not provided",IF(I29<3,"Poor",IF(I29>4.5,"Excellent","Average"))) -> Average
A30: Foldable Overbed Table/Desk | B30: 1650 | C30: 2150 | D30: =IF(B30<1300,"Budget friendly",IF(B30>2500,"Premium","Value")) -> Value | E30: =Table22[[#This Row],[Old price]]-Table22[[#This Row],[Current price]] -> 500 | F30: 0.23 | G30: =IF(F30<0.2,"Low discount",IF(F30>0.4,"High discount","Medium discount")) -> Medium discount | H30: 14 | I30: 4.4 | J30: =IF(ISBLANK(I30),"Not provided",IF(I30<3,"Poor",IF(I30>4.5,"Excellent","Average"))) -> Average
A31: LASA 3 Tier Bamboo Shoe Bench Storage Shelf | B31: 2048 | C31: 4500 | D31: =IF(B31<1300,"Budget friendly",IF(B31>2500,"Premium","Value")) -> Value | E31: =Table22[[#This Row],[Old price]]-Table22[[#This Row],[Current price]] -> 2452 | F31: 0.54 | G31: =IF(F31<0.2,"Low discount",IF(F31>0.4,"High discount","Medium discount")) -> High discount | H31: 7 | I31: 4.3 | J31: =IF(ISBLANK(I31),"Not provided",IF(I31<3,"Poor",IF(I31>4.5,"Excellent","Average"))) -> Average
A32: Electronic Digital Display Vernier Caliper | B32: 420 | C32: 647 | D32: =IF(B32<1300,"Budget friendly",IF(B32>2500,"Premium","Value")) -> Budget friendly | E32: =Table22[[#This Row],[Old price]]-Table22[[#This Row],[Current price]] -> 227 | F32: 0.35 | G32: =IF(F32<0.2,"Low discount",IF(F32>0.4,"High discount","Medium discount")) -> Medium discount | H32: 49 | I32: 4.6 | J32: =IF(ISBLANK(I32),"Not provided",IF(I32<3,"Poor",IF(I32>4.5,"Excellent","Average"))) -> Excellent
A33: Portable Wardrobe Nonwoven With 3 Hanging Rods And 6 Storage Shelves | B33: 2880 | C33: 3520 | D33: =IF(B33<1300,"Budget friendly",IF(B33>2500,"Premium","Value")) -> Premium | E33: =Table22[[#This Row],[Old price]]-Table22[[#This Row],[Current price]] -> 640 | F33: 0.18 | G33: =IF(F33<0.2,"Low discount",IF(F33>0.4,"High discount","Medium discount")) -> Low discount | H33: 12 | I33: 3.8 | J33: =IF(ISBLANK(I33),"Not provided",IF(I33<3,"Poor",IF(I33>4.5,"Excellent","Average"))) -> Average
A34: 12 Litre Black Insulated Lunch Box | B34: 1350 | C34: 1990 | D34: =IF(B34<1300,"Budget friendly",IF(B34>2500,"Premium","Value")) -> Value | E34: =Table22[[#This Row],[Old price]]-Table22[[#This Row],[Current price]] -> 640 | F34: 0.32 | G34: =IF(F34<0.2,"Low discount",IF(F34>0.4,"High discount","Medium discount")) -> Medium discount | H34: 13 | I34: 3.8 | J34: =IF(ISBLANK(I34),"Not provided",IF(I34<3,"Poor",IF(I34>4.5,"Excellent","Average"))) -> Average
A35: 52 Pieces Cake Decorating Tool Set Gift Kit Baking Supplies | B35: 1758 | C35: 2499 | D35: =IF(B35<1300,"Budget friendly",IF(B35>2500,"Premium","Value")) -> Value | E35: =Table22[[#This Row],[Old price]]-Table22[[#This Row],[Current price]] -> 741 | F35: 0.3 | G35: =IF(F35<0.2,"Low discount",IF(F35>0.4,"High discount","Medium discount")) -> Medium discount | H35: 20 | I35: 4.1 | J35: =IF(ISBLANK(I35),"Not provided",IF(I35<3,"Poor",IF(I35>4.5,"Excellent","Average"))) -> Average
A36: MultiFunctional Storage Rack Multi-layer Bookshelf | B36: 2200 | C36: 4080 | D36: =IF(B36<1300,"Budget friendly",IF(B36>2500,"Premium","Value")) -> Value | E36: =Table22[[#This Row],[Old price]]-Table22[[#This Row],[Current price]] -> 1880 | F36: 0.46 | G36: =IF(F36<0.2,"Low discount",IF(F36>0.4,"High discount","Medium discount")) -> High discount | J36: =IF(ISBLANK(I36),"Not provided",IF(I36<3,"Poor",IF(I36>4.5,"Excellent","Average"))) -> Not provided
A37: Exfoliate And Exfoliate Face Towel - Black | B37: 185 | C37: 382 | D37: =IF(B37<1300,"Budget friendly",IF(B37>2500,"Premium","Value")) -> Budget friendly | E37: =Table22[[#This Row],[Old price]]-Table22[[#This Row],[Current price]] -> 197 | F37: 0.52 | G37: =IF(F37<0.2,"Low discount",IF(F37>0.4,"High discount","Medium discount")) -> High discount | H37: 9 | I37: 4.3 | J37: =IF(ISBLANK(I37),"Not provided",IF(I37<3,"Poor",IF(I37>4.5,"Excellent","Average"))) -> Average
A38: 12 Litre Insulated Lunch Box Grey | B38: 980 | C38: 1490 | D38: =IF(B38<1300,"Budget friendly",IF(B38>2500,"Premium","Value")) -> Budget friendly | E38: =Table22[[#This Row],[Old price]]-Table22[[#This Row],[Current price]] -> 510 | F38: 0.34 | G38: =IF(F38<0.2,"Low discount",IF(F38>0.4,"High discount","Medium discount")) -> Medium discount | H38: 12 | I38: 4.7 | J38: =IF(ISBLANK(I38),"Not provided",IF(I38<3,"Poor",IF(I38>4.5,"Excellent","Average"))) -> Excellent
A39: LED Eye Protection Desk Lamp , Study, Reading, USB Fan - Double Pen Holder | B39: 1820 | C39: 3490 | D39: =IF(B39<1300,"Budget friendly",IF(B39>2500,"Premium","Value")) -> Value | E39: =Table22[[#This Row],[Old price]]-Table22[[#This Row],[Current price]] -> 1670 | F39: 0.48 | G39: =IF(F39<0.2,"Low discount",IF(F39>0.4,"High discount","Medium discount")) -> High discount | H39: 9 | I39: 4.3 | J39: =IF(ISBLANK(I39),"Not provided",IF(I39<3,"Poor",IF(I39>4.5,"Excellent","Average"))) -> Average
A40: 53Pcs/Set Yarn Knitting Crochet Hooks With Bag - Fortune Cat | B40: 1940 | C40: 2650 | D40: =IF(B40<1300,"Budget friendly",IF(B40>2500,"Premium","Value")) -> Value | E40: =Table22[[#This Row],[Old price]]-Table22[[#This Row],[Current price]] -> 710 | F40: 0.27 | G40: =IF(F40<0.2,"Low discount",IF(F40>0.4,"High discount","Medium discount")) -> Medium discount | H40: 20 | I40: 4.7 | J40: =IF(ISBLANK(I40),"Not provided",IF(I40<3,"Poor",IF(I40>4.5,"Excellent","Average"))) -> Excellent
A41: 53 Pieces/Set Yarn Knitting Crochet Hooks With Bag - Pansies | B41: 1980 | C41: 2699 | D41: =IF(B41<1300,"Budget friendly",IF(B41>2500,"Premium","Value")) -> Value | E41: =Table22[[#This Row],[Old price]]-Table22[[#This Row],[Current price]] -> 719 | F41: 0.27 | G41: =IF(F41<0.2,"Low discount",IF(F41>0.4,"High discount","Medium discount")) -> Medium discount | H41: 32 | I41: 4.5 | J41: =IF(ISBLANK(I41),"Not provided",IF(I41<3,"Poor",IF(I41>4.5,"Excellent","Average"))) -> Average
A42: DIY File Folder, Office Drawer File Holder, Pen Holder, Desktop Storage Rack | B42: 1620 | C42: 2690 | D42: =IF(B42<1300,"Budget friendly",IF(B42>2500,"Premium","Value")) -> Value | E42: =Table22[[#This Row],[Old price]]-Table22[[#This Row],[Current price]] -> 1070 | F42: 0.4 | G42: =IF(F42<0.2,"Low discount",IF(F42>0.4,"High discount","Medium discount")) -> Medium discount | H42: 1 | I42: 5 | J42: =IF(ISBLANK(I42),"Not provided",IF(I42<3,"Poor",IF(I42>4.5,"Excellent","Average"))) -> Excellent
A43: Classic Black Cat Cotton Hemp Pillow Case For Home Car | B43: 171 | C43: 360 | D43: =IF(B43<1300,"Budget friendly",IF(B43>2500,"Premium","Value")) -> Budget friendly | E43: =Table22[[#This Row],[Old price]]-Table22[[#This Row],[Current price]] -> 189 | F43: 0.53 | G43: =IF(F43<0.2,"Low discount",IF(F43>0.4,"High discount","Medium discount")) -> High discount | H43: 2 | I43: 5 | J43: =IF(ISBLANK(I43),"Not provided",IF(I43<3,"Poor",IF(I43>4.5,"Excellent","Average"))) -> Excellent
A44: Punch-free Great Load Bearing Bathroom Storage Rack Wall Shelf-White | B44: 389 | C44: 656 | D44: =IF(B44<1300,"Budget friendly",IF(B44>2500,"Premium","Value")) -> Budget friendly | E44: =Table22[[#This Row],[Old price]]-Table22[[#This Row],[Current price]] -> 267 | F44: 0.41 | G44: =IF(F44<0.2,"Low discount",IF(F44>0.4,"High discount","Medium discount")) -> High discount | H44: 36 | I44: 4.3 | J44: =IF(ISBLANK(I44),"Not provided",IF(I44<3,"Poor",IF(I44>4.5,"Excellent","Average"))) -> Average
A45: 1/2/3 Seater Elastic Sofa Cover,Living Room/Home Decor Chair Cover-Grey | B45: 1800 | C45: 2700 | D45: =IF(B45<1300,"Budget friendly",IF(B45>2500,"Premium","Value")) -> Value | E45: =Table22[[#This Row],[Old price]]-Table22[[#This Row],[Current price]] -> 900 | F45: 0.38 | G45: =IF(F45<0.2,"Low discount",IF(F45>0.4,"High discount","Medium discount")) -> Medium discount | H45: 2 | I45: 4.5 | J45: =IF(ISBLANK(I45),"Not provided",IF(I45<3,"Poor",IF(I45>4.5,"Excellent","Average"))) -> Average
A46: LASA Stainless Steel Double Wall Mount Soap Dispenser - 500ml | B46: 2750 | C46: 4471 | D46: =IF(B46<1300,"Budget friendly",IF(B46>2500,"Premium","Value")) -> Premium | E46: =Table22[[#This Row],[Old price]]-Table22[[#This Row],[Current price]] -> 1721 | F46: 0.38 | G46: =IF(F46<0.2,"Low discount",IF(F46>0.4,"High discount","Medium discount")) -> Medium discount | J46: =IF(ISBLANK(I46),"Not provided",IF(I46<3,"Poor",IF(I46>4.5,"Excellent","Average"))) -> Not provided
A47: 4M Float Switch Water Level Controller -Water Tank | B47: 475 | C47: 931 | D47: =IF(B47<1300,"Budget friendly",IF(B47>2500,"Premium","Value")) -> Budget friendly | E47: =Table22[[#This Row],[Old price]]-Table22[[#This Row],[Current price]] -> 456 | F47: 0.49 | G47: =IF(F47<0.2,"Low discount",IF(F47>0.4,"High discount","Medium discount")) -> High discount | J47: =IF(ISBLANK(I47),"Not provided",IF(I47<3,"Poor",IF(I47>4.5,"Excellent","Average"))) -> Not provided
A48: Modern Sofa Throw Pillow Cover-45x45cm-Blue&Red | B48: 238 | C48: 476 | D48: =IF(B48<1300,"Budget friendly",IF(B48>2500,"Premium","Value")) -> Budget friendly | E48: =Table22[[#This Row],[Old price]]-Table22[[#This Row],[Current price]] -> 238 | F48: 0.5 | G48: =IF(F48<0.2,"Low discount",IF(F48>0.4,"High discount","Medium discount")) -> High discount | J48: =IF(ISBLANK(I48),"Not provided",IF(I48<3,"Poor",IF(I48>4.5,"Excellent","Average"))) -> Not provided
A49: Balloon Insert, Birthday Party Balloon Set, PU Leather | B49: 610 | C49: 1060 | D49: =IF(B49<1300,"Budget friendly",IF(B49>2500,"Premium","Value")) -> Budget friendly | E49: =Table22[[#This Row],[Old price]]-Table22[[#This Row],[Current price]] -> 450 | F49: 0.42 | G49: =IF(F49<0.2,"Low discount",IF(F49>0.4,"High discount","Medium discount")) -> High discount | J49: =IF(ISBLANK(I49),"Not provided",IF(I49<3,"Poor",IF(I49>4.5,"Excellent","Average"))) -> Not provided
A50: Shower Cap Wide Elastic Band Cover Reusable Bashroom Cap | B50: 2132 | C50: 2169 | D50: =IF(B50<1300,"Budget friendly",IF(B50>2500,"Premium","Value")) -> Value | E50: =Table22[[#This Row],[Old price]]-Table22[[#This Row],[Current price]] -> 37 | F50: 0.02 | G50: =IF(F50<0.2,"Low discount",IF(F50>0.4,"High discount","Medium discount")) -> Low discount | J50: =IF(ISBLANK(I50),"Not provided",IF(I50<3,"Poor",IF(I50>4.5,"Excellent","Average"))) -> Not provided
A51: Christmas Elk Fence Yard Lawn Decorations Cute For Holidays | B51: 999 | C51: 2000 | D51: =IF(B51<1300,"Budget friendly",IF(B51>2500,"Premium","Value")) -> Budget friendly | E51: =Table22[[#This Row],[Old price]]-Table22[[#This Row],[Current price]] -> 1001 | F51: 0.5 | G51: =IF(F51<0.2,"Low discount",IF(F51>0.4,"High discount","Medium discount")) -> High discount | J51: =IF(ISBLANK(I51),"Not provided",IF(I51<3,"Poor",IF(I51>4.5,"Excellent","Average"))) -> Not provided
...

Sheet High discount,low rating pdts
A1: These products have the highest discounts (>40%) and are poorly rated (<3 out of 5)
A3: Discount category | B3: High discount
A4: Rating category | B4: Poor
A6: Row Labels | B6: Average of Discount(%) | C6: Average of Rating (out of 5)
A7: 120W Cordless Vacuum Cleaners Handheld Electric Vacuum Cleaner | B7: 0.49 | C7: 2.8
A8: 380ML USB Rechargeable Portable Small Blenders And Juicers | B8: 0.5 | C8: 2.3
A9: 5-PCS Stainless Steel Cooking Pot Set With Steamed Slices | B9: 0.55 | C9: 2.1
A10: 7-piece Set Of Storage Bags, Travel Storage Bags, Shoe Bags | B10: 0.47 | C10: 2.2
A11: Agapeon Toothbrush Holder And Toothpaste Dispenser | B11: 0.45 | C11: 2.6
A12: Artificial Potted Flowers Room Decorative Flowers (2 Pieces) | B12: 0.45 | C12: 2.2
A13: Electric LED UV Mosquito Killer Lamp, Outdoor/Indoor Fly Killer Trap Light -USB | B13: 0.47 | C13: 2.1
A14: Intelligent LED Body Sensor Wireless Lighting Night Light USB | B14: 0.52 | C14: 2.7
A15: Wall-mounted Sticker Punch-free Plug Fixer | B15: 0.5 | C15: 2
A16: Watercolour Gold Foil Textured Print Pillow Cover | B16: 0.43 | C16: 2.3
A17: Grand Total | B17: 0.483 | C17: 2.33

Sheet Product customer engagement
A1: Products with the strongest customer engagement are as shown below. These products were rated "Excellent" ie rating >4.5 and have over 20 customer reviews.
A3: Rating category | B3: Excellent
A5: Row Labels | B5: Sum of Review | C5: Average of Rating (out of 5)
A6: 100 Pcs Crochet Hook Tool Set Knitting Hook Set With Box | B6: 39 | C6: 4.7
A7: 137 Pieces Cake Decorating Tool Set Baking Supplies | B7: 55 | C7: 4.6
A8: 3D Waterproof EVA Plastic Shower Curtain 1.8*2Mtrs | B8: 44 | C8: 4.6
A9: Electronic Digital Display Vernier Caliper | B9: 49 | C9: 4.6
A10: Portable Mini Cordless Car Vacuum Cleaner - Blue | B10: 24 | C10: 4.6
A11: Grand Total | B11: 211 | C11: 4.62
